Workbook
Name L_Bauteile: Stammdaten!$A$5:$A$41
Name L_Lagen: Stammdaten!$B$5:$B$41
Name L_Material: Stammdaten!$D$5:$D$41
Name L_Dichte: Stammdaten!$E$5:$E$41
Name L_Glanz: Stammdaten!$G$5:$G$41
Name L_Struktur: Stammdaten!$H$5:$H$41
Name L_Seite: Stammdaten!$I$5:$I$41
Name L_Lieferung: Stammdaten!$J$5:$J$41
Name L_JaNein: Stammdaten!$K$5:$K$6
Name L_Tafel: Stammdaten!$M$5:$M$41
Name L_TafelB: Stammdaten!$N$5:$N$41
Name L_TafelL: Stammdaten!$O$5:$O$41
Name P_NR: Projekt!$C$6
Name P_NAME: Projekt!$C$7
Name P_ADRESSE: Projekt!$C$8
Name P_KUNDE: Projekt!$C$9
Name P_KONTAKT: Projekt!$C$10
Name P_PL: Projekt!$C$11
Name P_DATUM: Projekt!$C$12
Name P_BEARBEITER: Projekt!$C$13
Name P_BESCHICHTER: Projekt!$F$6
Name P_RAL: Projekt!$F$7
Name P_GLANZ: Projekt!$F$8
Name P_STRUKTUR: Projekt!$F$9
Name P_SEITE: Projekt!$F$10
Name P_TERMIN: Projekt!$F$11
Name P_LIEFERUNG: Projekt!$F$12
Name P_QUALI: Projekt!$F$13
Name P_MAT: Projekt!$C$16
Name P_DICKE: Projekt!$C$17
Name P_BESCH: Projekt!$C$18
Name P_VERSCHNITT: Projekt!$F$16
Name P_TAFEL: Projekt!$F$17
Name P_NOTIZ: Projekt!$B$21

Sheet Projekt
F1: MATERIALAUSZUG
F2: =IF(P_NR="","Projekt",P_NR&" · "&P_NAME)
B5: PROJEKT | E5: BESCHICHTUNG
B6: Projekt-Nr. | C6: {{NR}} | E6: Beschichter (Firma) | F6: {{BESCHICHTER}}
B7: Projekt | C7: {{NAME}} | E7: Farbe / RAL
B8: Adresse / Baustelle | C8: {{ADRESSE}} | E8: Glanzgrad
B9: Kunde | C9: {{KUNDE}} | E9: Struktur
B10: Kontaktperson Kunde | C10: {{KONTAKT}} | E10: Beschichtungsseite | F10: Sichtseite
B11: Projektleiter 2R | C11: {{PL}} | E11: Liefertermin gewünscht
B12: Datum | C12: {{DATUM}} | E12: Lieferung / Abholung | F12: Anlieferung durch 2R
B13: Bearbeiter | C13: {{BEARBEITER}} | E13: Qualität / Norm
B15: STANDARDWERTE – gelten, wenn in den Positionen leer
B16: Material | C16: Aluminium | E16: Verschnitt | F16: 0.15
B17: Dicke (mm) | C17: 2 | E17: Tafelformat | F17: 1250 × 2500
B18: Beschichten | C18: Ja
B20: BEMERKUNG / NOTIZ / SKIZZE
B29: SO FUNKTIONIERT'S
B30: 1. Hier Projekt- und Beschichtungsangaben prüfen (von der App vorausgefüllt).
B31: 2. Blatt «Positionen»: pro Zeile ein Bauteil – Abwicklung, Länge, Anzahl. Weisse Spalten ausfüllen.
B32: 3. Blaue Spalten (lfm, m², kg) rechnen automatisch. Leere Material/Dicke/Beschichten = Standardwerte oben.
B33: 4. «Beschichtungsauftrag» = alle Positionen mit Beschichten «Ja» – druckfertig für den Beschichter.
B34: 5. «Materialauszug» = Summen nach Bauteil, Material/Dicke und Fassade (Stk · lfm · m² · kg).
B35: 6. «Tafelbedarf» = Anzahl Tafeln pro Material/Dicke inkl. Verschnitt und Längen-Warnung.
B36: 7. «Packliste» = alle Teile nach Fassade sortiert zum Abhaken beim Verladen/Abladen.
B37: 8. Auswahllisten (Bauteile, Fassaden, Material, Tafelformate) im Blatt «Stammdaten» ergänzen.

Sheet Positionen
A1: POSITIONEN | D1: =IF(P_NR="","",P_NR&" · "&P_NAME) | P1: =MAX(25,SUMPRODUCT(MAX((B6:B205<>"")*ROW(B6:B205))))
A2: Weisse Spalten ausfüllen · blaue Spalten (lfm, m², kg) rechnen automatisch · Material, Dicke, Beschichten und Farbe leer = Standardwerte aus Blatt «Projekt».
H3: =SUM(H6:H205) | J3: Total | K3: =SUM(K6:K205) | L3: =SUM(L6:L205) | M3: =SUM(M6:M205)
A4: Bsp. | B4: Brüstungsblech | C4: Südfassade | D4: Aluminium | E4: 2 | F4: 320 | G4: 2450 | H4: 6 | I4: Ja | J4: RAL 7016 | K4: 14.7 | L4: 4.704 | M4: 25.4 | N4: Beispiel – so wird ausgefüllt (wird nicht mitgerechnet) | P4: Hilfsspalten – nicht ändern
A5: Pos. | B5: Bauteil | C5: Lage / Fassade | D5: Material | E5: Dicke mm | F5: Abwicklung mm | G5: Länge mm | H5: Anzahl Stk | I5: Beschich- ten | J5: Farbe / RAL | K5: lfm auto | L5: m² auto | M5: kg auto | N5: Bemerkung | P5: Material eff. | Q5: Dicke eff. | R5: Beschichten eff. | S5: Farbe eff. | T5: Material·Dicke | U5: Nr. Beschichtung | V5: Nr. Bauteil | W5: Nr. Mat·Dicke | X5: Lage eff. | Y5: Nr. Lage | Z5: Sortierung Packliste | AA5: Teile pro Tafel | AB5: Tafeln (Zuschnitt) | AC5: Nr. Position
K6: =IF(OR($G6="",$H6=""),"",$G6*$H6/1000) | L6: =IF(OR(K6="",$F6=""),"",K6*$F6/1000) | M6: =IF(OR(L6="",Q6=""),"",IFERROR(L6*Q6*INDEX(L_Dichte,MATCH(P6,L_Material,0)),"")) | P6: =IF($B6="","",IF($D6="",P_MAT,$D6)) | Q6: =IF($B6="","",IF($E6="",P_DICKE,$E6)) | R6: =IF($B6="","",IF($I6="",P_BESCH,$I6)) | S6: =IF(R6<>"Ja","",IF($J6="",P_RAL,$J6)) | T6: =IF($B6="","",P6&" · "&Q6&" mm") | U6: =IF(R6="Ja",COUNTIF($R$6:R6,"Ja"),"") | V6: =IF($B6="","",IF(COUNTIF($B$6:$B6,$B6)=1,MAX($V$5:V5)+1,"")) | W6: =IF(T6="","",IF(COUNTIF($T$6:T6,T6)=1,MAX($W$5:W5)+1,"")) | X6: =IF($B6="","",IF($C6="","– ohne Angabe –",$C6)) | Y6: =IF(X6="","",IF(COUNTIF($X$6:X6,X6)=1,MAX($Y$5:Y5)+1,"")) | Z6: =IF($B6="","",INDEX($Y$6:$Y$205,MATCH(X6,$X$6:$X$205,0))*1000+ROW()-5) | AA6: =IF(OR($F6="",$G6="",T6=""),"",IFERROR(MAX(INT(INDEX(Tafelbedarf!$O$9:$O$48,MATCH(T6,Tafelbedarf!$A$9:$A$48,0))/$F6)*INT(INDEX(Tafelbedarf!$P$9:$P$48,MATCH(T6,Tafelbedarf!$A$9:$A$48,0))/$G6),INT(INDEX(Tafelbedarf!$P$9:$P$48,MATCH(T6,Tafelbedarf!$A$9:$A$48,0))/$F6)*INT(INDEX(Tafelbedarf!$O$9:$O$48,MATCH(T6,Tafelbedarf!$A$9:$A$48,0))/$G6)),"")) | AB6: =IF(OR(AA6="",$H6=""),"",IF(AA6=0,"",ROUNDUP($H6/AA6,0))) | AC6: =IF($B6="","",COUNTIF($B$6:$B6,"?*"))
K7: =IF(OR($G7="",$H7=""),"",$G7*$H7/1000) | L7: =IF(OR(K7="",$F7=""),"",K7*$F7/1000) | M7: =IF(OR(L7="",Q7=""),"",IFERROR(L7*Q7*INDEX(L_Dichte,MATCH(P7,L_Material,0)),"")) | P7: =IF($B7="","",IF($D7="",P_MAT,$D7)) | Q7: =IF($B7="","",IF($E7="",P_DICKE,$E7)) | R7: =IF($B7="","",IF($I7="",P_BESCH,$I7)) | S7: =IF(R7<>"Ja","",IF($J7="",P_RAL,$J7)) | T7: =IF($B7="","",P7&" · "&Q7&" mm") | U7: =IF(R7="Ja",COUNTIF($R$6:R7,"Ja"),"") | V7: =IF($B7="","",IF(COUNTIF($B$6:$B7,$B7)=1,MAX($V$5:V6)+1,"")) | W7: =IF(T7="","",IF(COUNTIF($T$6:T7,T7)=1,MAX($W$5:W6)+1,"")) | X7: =IF($B7="","",IF($C7="","– ohne Angabe –",$C7)) | Y7: =IF(X7="","",IF(COUNTIF($X$6:X7,X7)=1,MAX($Y$5:Y6)+1,"")) | Z7: =IF($B7="","",INDEX($Y$6:$Y$205,MATCH(X7,$X$6:$X$205,0))*1000+ROW()-5) | AA7: =IF(OR($F7="",$G7="",T7=""),"",IFERROR(MAX(INT(INDEX(Tafelbedarf!$O$9:$O$48,MATCH(T7,Tafelbedarf!$A$9:$A$48,0))/$F7)*INT(INDEX(Tafelbedarf!$P$9:$P$48,MATCH(T7,Tafelbedarf!$A$9:$A$48,0))/$G7),INT(INDEX(Tafelbedarf!$P$9:$P$48,MATCH(T7,Tafelbedarf!$A$9:$A$48,0))/$F7)*INT(INDEX(Tafelbedarf!$O$9:$O$48,MATCH(T7,Tafelbedarf!$A$9:$A$48,0))/$G7)),"")) | AB7: =IF(OR(AA7="",$H7=""),"",IF(AA7=0,"",ROUNDUP($H7/AA7,0))) | AC7: =IF($B7="","",COUNTIF($B$6:$B7,"?*"))
K8: =IF(OR($G8="",$H8=""),"",$G8*$H8/1000) | L8: =IF(OR(K8="",$F8=""),"",K8*$F8/1000) | M8: =IF(OR(L8="",Q8=""),"",IFERROR(L8*Q8*INDEX(L_Dichte,MATCH(P8,L_Material,0)),"")) | P8: =IF($B8="","",IF($D8="",P_MAT,$D8)) | Q8: =IF($B8="","",IF($E8="",P_DICKE,$E8)) | R8: =IF($B8="","",IF($I8="",P_BESCH,$I8)) | S8: =IF(R8<>"Ja","",IF($J8="",P_RAL,$J8)) | T8: =IF($B8="","",P8&" · "&Q8&" mm") | U8: =IF(R8="Ja",COUNTIF($R$6:R8,"Ja"),"") | V8: =IF($B8="","",IF(COUNTIF($B$6:$B8,$B8)=1,MAX($V$5:V7)+1,"")) | W8: =IF(T8="","",IF(COUNTIF($T$6:T8,T8)=1,MAX($W$5:W7)+1,"")) | X8: =IF($B8="","",IF($C8="","– ohne Angabe –",$C8)) | Y8: =IF(X8="","",IF(COUNTIF($X$6:X8,X8)=1,MAX($Y$5:Y7)+1,"")) | Z8: =IF($B8="","",INDEX($Y$6:$Y$205,MATCH(X8,$X$6:$X$205,0))*1000+ROW()-5) | AA8: =IF(OR($F8="",$G8="",T8=""),"",IFERROR(MAX(INT(INDEX(Tafelbedarf!$O$9:$O$48,MATCH(T8,Tafelbedarf!$A$9:$A$48,0))/$F8)*INT(INDEX(Tafelbedarf!$P$9:$P$48,MATCH(T8,Tafelbedarf!$A$9:$A$48,0))/$G8),INT(INDEX(Tafelbedarf!$P$9:$P$48,MATCH(T8,Tafelbedarf!$A$9:$A$48,0))/$F8)*INT(INDEX(Tafelbedarf!$O$9:$O$48,MATCH(T8,Tafelbedarf!$A$9:$A$48,0))/$G8)),"")) | AB8: =IF(OR(AA8="",$H8=""),"",IF(AA8=0,"",ROUNDUP($H8/AA8,0))) | AC8: =IF($B8="","",COUNTIF($B$6:$B8,"?*"))
K9: =IF(OR($G9="",$H9=""),"",$G9*$H9/1000) | L9: =IF(OR(K9="",$F9=""),"",K9*$F9/1000) | M9: =IF(OR(L9="",Q9=""),"",IFERROR(L9*Q9*INDEX(L_Dichte,MATCH(P9,L_Material,0)),"")) | P9: =IF($B9="","",IF($D9="",P_MAT,$D9)) | Q9: =IF($B9="","",IF($E9="",P_DICKE,$E9)) | R9: =IF($B9="","",IF($I9="",P_BESCH,$I9)) | S9: =IF(R9<>"Ja","",IF($J9="",P_RAL,$J9)) | T9: =IF($B9="","",P9&" · "&Q9&" mm") | U9: =IF(R9="Ja",COUNTIF($R$6:R9,"Ja"),"") | V9: =IF($B9="","",IF(COUNTIF($B$6:$B9,$B9)=1,MAX($V$5:V8)+1,"")) | W9: =IF(T9="","",IF(COUNTIF($T$6:T9,T9)=1,MAX($W$5:W8)+1,"")) | X9: =IF($B9="","",IF($C9="","– ohne Angabe –",$C9)) | Y9: =IF(X9="","",IF(COUNTIF($X$6:X9,X9)=1,MAX($Y$5:Y8)+1,"")) | Z9: =IF($B9="","",INDEX($Y$6:$Y$205,MATCH(X9,$X$6:$X$205,0))*1000+ROW()-5) | AA9: =IF(OR($F9="",$G9="",T9=""),"",IFERROR(MAX(INT(INDEX(Tafelbedarf!$O$9:$O$48,MATCH(T9,Tafelbedarf!$A$9:$A$48,0))/$F9)*INT(INDEX(Tafelbedarf!$P$9:$P$48,MATCH(T9,Tafelbedarf!$A$9:$A$48,0))/$G9),INT(INDEX(Tafelbedarf!$P$9:$P$48,MATCH(T9,Tafelbedarf!$A$9:$A$48,0))/$F9)*INT(INDEX(Tafelbedarf!$O$9:$O$48,MATCH(T9,Tafelbedarf!$A$9:$A$48,0))/$G9)),"")) | AB9: =IF(OR(AA9="",$H9=""),"",IF(AA9=0,"",ROUNDUP($H9/AA9,0))) | AC9: =IF($B9="","",COUNTIF($B$6:$B9,"?*"))
K10: =IF(OR($G10="",$H10=""),"",$G10*$H10/1000) | L10: =IF(OR(K10="",$F10=""),"",K10*$F10/1000) | M10: =IF(OR(L10="",Q10=""),"",IFERROR(L10*Q10*INDEX(L_Dichte,MATCH(P10,L_Material,0)),"")) | P10: =IF($B10="","",IF($D10="",P_MAT,$D10)) | Q10: =IF($B10="","",IF($E10="",P_DICKE,$E10)) | R10: =IF($B10="","",IF($I10="",P_BESCH,$I10)) | S10: =IF(R10<>"Ja","",IF($J10="",P_RAL,$J10)) | T10: =IF($B10="","",P10&" · "&Q10&" mm") | U10: =IF(R10="Ja",COUNTIF($R$6:R10,"Ja"),"") | V10: =IF($B10="","",IF(COUNTIF($B$6:$B10,$B10)=1,MAX($V$5:V9)+1,"")) | W10: =IF(T10="","",IF(COUNTIF($T$6:T10,T10)=1,MAX($W$5:W9)+1,"")) | X10: =IF($B10="","",IF($C10="","– ohne Angabe –",$C10)) | Y10: =IF(X10="","",IF(COUNTIF($X$6:X10,X10)=1,MAX($Y$5:Y9)+1,"")) | Z10: =IF($B10="","",INDEX($Y$6:$Y$205,MATCH(X10,$X$6:$X$205,0))*1000+ROW()-5) | AA10: =IF(OR($F10="",$G10="",T10=""),"",IFERROR(MAX(INT(INDEX(Tafelbedarf!$O$9:$O$48,MATCH(T10,Tafelbedarf!$A$9:$A$48,0))/$F10)*INT(INDEX(Tafelbedarf!$P$9:$P$48,MATCH(T10,Tafelbedarf!$A$9:$A$48,0))/$G10),INT(INDEX(Tafelbedarf!$P$9:$P$48,MATCH(T10,Tafelbedarf!$A$9:$A$48,0))/$F10)*INT(INDEX(Tafelbedarf!$O$9:$O$48,MATCH(T10,Tafelbedarf!$A$9:$A$48,0))/$G10)),"")) | AB10: =IF(OR(AA10="",$H10=""),"",IF(AA10=0,"",ROUNDUP($H10/AA10,0))) | AC10: =IF($B10="","",COUNTIF($B$6:$B10,"?*"))
K11: =IF(OR($G11="",$H11=""),"",$G11*$H11/1000) | L11: =IF(OR(K11="",$F11=""),"",K11*$F11/1000) | M11: =IF(OR(L11="",Q11=""),"",IFERROR(L11*Q11*INDEX(L_Dichte,MATCH(P11,L_Material,0)),"")) | P11: =IF($B11="","",IF($D11="",P_MAT,$D11)) | Q11: =IF($B11="","",IF($E11="",P_DICKE,$E11)) | R11: =IF($B11="","",IF($I11="",P_BESCH,$I11)) | S11: =IF(R11<>"Ja","",IF($J11="",P_RAL,$J11)) | T11: =IF($B11="","",P11&" · "&Q11&" mm") | U11: =IF(R11="Ja",COUNTIF($R$6:R11,"Ja"),"") | V11: =IF($B11="","",IF(COUNTIF($B$6:$B11,$B11)=1,MAX($V$5:V10)+1,"")) | W11: =IF(T11="","",IF(COUNTIF($T$6:T11,T11)=1,MAX($W$5:W10)+1,"")) | X11: =IF($B11="","",IF($C11="","– ohne Angabe –",$C11)) | Y11: =IF(X11="","",IF(COUNTIF($X$6:X11,X11)=1,MAX($Y$5:Y10)+1,"")) | Z11: =IF($B11="","",INDEX($Y$6:$Y$205,MATCH(X11,$X$6:$X$205,0))*1000+ROW()-5) | AA11: =IF(OR($F11="",$G11="",T11=""),"",IFERROR(MAX(INT(INDEX(Tafelbedarf!$O$9:$O$48,MATCH(T11,Tafelbedarf!$A$9:$A$48,0))/$F11)*INT(INDEX(Tafelbedarf!$P$9:$P$48,MATCH(T11,Tafelbedarf!$A$9:$A$48,0))/$G11),INT(INDEX(Tafelbedarf!$P$9:$P$48,MATCH(T11,Tafelbedarf!$A$9:$A$48,0))/$F11)*INT(INDEX(Tafelbedarf!$O$9:$O$48,MATCH(T11,Tafelbedarf!$A$9:$A$48,0))/$G11)),"")) | AB11: =IF(OR(AA11="",$H11=""),"",IF(AA11=0,"",ROUNDUP($H11/AA11,0))) | AC11: =IF($B11="","",COUNTIF($B$6:$B11,"?*"))
K12: =IF(OR($G12="",$H12=""),"",$G12*$H12/1000) | L12: =IF(OR(K12="",$F12=""),"",K12*$F12/1000) | M12: =IF(OR(L12="",Q12=""),"",IFERROR(L12*Q12*INDEX(L_Dichte,MATCH(P12,L_Material,0)),"")) | P12: =IF($B12="","",IF($D12="",P_MAT,$D12)) | Q12: =IF($B12="","",IF($E12="",P_DICKE,$E12)) | R12: =IF($B12="","",IF($I12="",P_BESCH,$I12)) | S12: =IF(R12<>"Ja","",IF($J12="",P_RAL,$J12)) | T12: =IF($B12="","",P12&" · "&Q12&" mm") | U12: =IF(R12="Ja",COUNTIF($R$6:R12,"Ja"),"") | V12: =IF($B12="","",IF(COUNTIF($B$6:$B12,$B12)=1,MAX($V$5:V11)+1,"")) | W12: =IF(T12="","",IF(COUNTIF($T$6:T12,T12)=1,MAX($W$5:W11)+1,"")) | X12: =IF($B12="","",IF($C12="","– ohne Angabe –",$C12)) | Y12: =IF(X12="","",IF(COUNTIF($X$6:X12,X12)=1,MAX($Y$5:Y11)+1,"")) | Z12: =IF($B12="","",INDEX($Y$6:$Y$205,MATCH(X12,$X$6:$X$205,0))*1000+ROW()-5) | AA12: =IF(OR($F12="",$G12="",T12=""),"",IFERROR(MAX(INT(INDEX(Tafelbedarf!$O$9:$O$48,MATCH(T12,Tafelbedarf!$A$9:$A$48,0))/$F12)*INT(INDEX(Tafelbedarf!$P$9:$P$48,MATCH(T12,Tafelbedarf!$A$9:$A$48,0))/$G12),INT(INDEX(Tafelbedarf!$P$9:$P$48,MATCH(T12,Tafelbedarf!$A$9:$A$48,0))/$F12)*INT(INDEX(Tafelbedarf!$O$9:$O$48,MATCH(T12,Tafelbedarf!$A$9:$A$48,0))/$G12)),"")) | AB12: =IF(OR(AA12="",$H12=""),"",IF(AA12=0,"",ROUNDUP($H12/AA12,0))) | AC12: =IF($B12="","",COUNTIF($B$6:$B12,"?*"))
K13: =IF(OR($G13="",$H13=""),"",$G13*$H13/1000) | L13: =IF(OR(K13="",$F13=""),"",K13*$F13/1000) | M13: =IF(OR(L13="",Q13=""),"",IFERROR(L13*Q13*INDEX(L_Dichte,MATCH(P13,L_Material,0)),"")) | P13: =IF($B13="","",IF($D13="",P_MAT,$D13)) | Q13: =IF($B13="","",IF($E13="",P_DICKE,$E13)) | R13: =IF($B13="","",IF($I13="",P_BESCH,$I13)) | S13: =IF(R13<>"Ja","",IF($J13="",P_RAL,$J13)) | T13: =IF($B13="","",P13&" · "&Q13&" mm") | U13: =IF(R13="Ja",COUNTIF($R$6:R13,"Ja"),"") | V13: =IF($B13="","",IF(COUNTIF($B$6:$B13,$B13)=1,MAX($V$5:V12)+1,"")) | W13: =IF(T13="","",IF(COUNTIF($T$6:T13,T13)=1,MAX($W$5:W12)+1,"")) | X13: =IF($B13="","",IF($C13="","– ohne Angabe –",$C13)) | Y13: =IF(X13="","",IF(COUNTIF($X$6:X13,X13)=1,MAX($Y$5:Y12)+1,"")) | Z13: =IF($B13="","",INDEX($Y$6:$Y$205,MATCH(X13,$X$6:$X$205,0))*1000+ROW()-5) | AA13: =IF(OR($F13="",$G13="",T13=""),"",IFERROR(MAX(INT(INDEX(Tafelbedarf!$O$9:$O$48,MATCH(T13,Tafelbedarf!$A$9:$A$48,0))/$F13)*INT(INDEX(Tafelbedarf!$P$9:$P$48,MATCH(T13,Tafelbedarf!$A$9:$A$48,0))/$G13),INT(INDEX(Tafelbedarf!$P$9:$P$48,MATCH(T13,Tafelbedarf!$A$9:$A$48,0))/$F13)*INT(INDEX(Tafelbedarf!$O$9:$O$48,MATCH(T13,Tafelbedarf!$A$9:$A$48,0))/$G13)),"")) | AB13: =IF(OR(AA13="",$H13=""),"",IF(AA13=0,"",ROUNDUP($H13/AA13,0))) | AC13: =IF($B13="","",COUNTIF($B$6:$B13,"?*"))
K14: =IF(OR($G14="",$H14=""),"",$G14*$H14/1000) | L14: =IF(OR(K14="",$F14=""),"",K14*$F14/1000) | M14: =IF(OR(L14="",Q14=""),"",IFERROR(L14*Q14*INDEX(L_Dichte,MATCH(P14,L_Material,0)),"")) | P14: =IF($B14="","",IF($D14="",P_MAT,$D14)) | Q14: =IF($B14="","",IF($E14="",P_DICKE,$E14)) | R14: =IF($B14="","",IF($I14="",P_BESCH,$I14)) | S14: =IF(R14<>"Ja","",IF($J14="",P_RAL,$J14)) | T14: =IF($B14="","",P14&" · "&Q14&" mm") | U14: =IF(R14="Ja",COUNTIF($R$6:R14,"Ja"),"") | V14: =IF($B14="","",IF(COUNTIF($B$6:$B14,$B14)=1,MAX($V$5:V13)+1,"")) | W14: =IF(T14="","",IF(COUNTIF($T$6:T14,T14)=1,MAX($W$5:W13)+1,"")) | X14: =IF($B14="","",IF($C14="","– ohne Angabe –",$C14)) | Y14: =IF(X14="","",IF(COUNTIF($X$6:X14,X14)=1,MAX($Y$5:Y13)+1,"")) | Z14: =IF($B14="","",INDEX($Y$6:$Y$205,MATCH(X14,$X$6:$X$205,0))*1000+ROW()-5) | AA14: =IF(OR($F14="",$G14="",T14=""),"",IFERROR(MAX(INT(INDEX(Tafelbedarf!$O$9:$O$48,MATCH(T14,Tafelbedarf!$A$9:$A$48,0))/$F14)*INT(INDEX(Tafelbedarf!$P$9:$P$48,MATCH(T14,Tafelbedarf!$A$9:$A$48,0))/$G14),INT(INDEX(Tafelbedarf!$P$9:$P$48,MATCH(T14,Tafelbedarf!$A$9:$A$48,0))/$F14)*INT(INDEX(Tafelbedarf!$O$9:$O$48,MATCH(T14,Tafelbedarf!$A$9:$A$48,0))/$G14)),"")) | AB14: =IF(OR(AA14="",$H14=""),"",IF(AA14=0,"",ROUNDUP($H14/AA14,0))) | AC14: =IF($B14="","",COUNTIF($B$6:$B14,"?*"))
K15: =IF(OR($G15="",$H15=""),"",$G15*$H15/1000) | L15: =IF(OR(K15="",$F15=""),"",K15*$F15/1000) | M15: =IF(OR(L15="",Q15=""),"",IFERROR(L15*Q15*INDEX(L_Dichte,MATCH(P15,L_Material,0)),"")) | P15: =IF($B15="","",IF($D15="",P_MAT,$D15)) | Q15: =IF($B15="","",IF($E15="",P_DICKE,$E15)) | R15: =IF($B15="","",IF($I15="",P_BESCH,$I15)) | S15: =IF(R15<>"Ja","",IF($J15="",P_RAL,$J15)) | T15: =IF($B15="","",P15&" · "&Q15&" mm") | U15: =IF(R15="Ja",COUNTIF($R$6:R15,"Ja"),"") | V15: =IF($B15="","",IF(COUNTIF($B$6:$B15,$B15)=1,MAX($V$5:V14)+1,"")) | W15: =IF(T15="","",IF(COUNTIF($T$6:T15,T15)=1,MAX($W$5:W14)+1,"")) | X15: =IF($B15="","",IF($C15="","– ohne Angabe –",$C15)) | Y15: =IF(X15="","",IF(COUNTIF($X$6:X15,X15)=1,MAX($Y$5:Y14)+1,"")) | Z15: =IF($B15="","",INDEX($Y$6:$Y$205,MATCH(X15,$X$6:$X$205,0))*1000+ROW()-5) | AA15: =IF(OR($F15="",$G15="",T15=""),"",IFERROR(MAX(INT(INDEX(Tafelbedarf!$O$9:$O$48,MATCH(T15,Tafelbedarf!$A$9:$A$48,0))/$F15)*INT(INDEX(Tafelbedarf!$P$9:$P$48,MATCH(T15,Tafelbedarf!$A$9:$A$48,0))/$G15),INT(INDEX(Tafelbedarf!$P$9:$P$48,MATCH(T15,Tafelbedarf!$A$9:$A$48,0))/$F15)*INT(INDEX(Tafelbedarf!$O$9:$O$48,MATCH(T15,Tafelbedarf!$A$9:$A$48,0))/$G15)),"")) | AB15: =IF(OR(AA15="",$H15=""),"",IF(AA15=0,"",ROUNDUP($H15/AA15,0))) | AC15: =IF($B15="","",COUNTIF($B$6:$B15,"?*"))
K16: =IF(OR($G16="",$H16=""),"",$G16*$H16/1000) | L16: =IF(OR(K16="",$F16=""),"",K16*$F16/1000) | M16: =IF(OR(L16="",Q16=""),"",IFERROR(L16*Q16*INDEX(L_Dichte,MATCH(P16,L_Material,0)),"")) | P16: =IF($B16="","",IF($D16="",P_MAT,$D16)) | Q16: =IF($B16="","",IF($E16="",P_DICKE,$E16)) | R16: =IF($B16="","",IF($I16="",P_BESCH,$I16)) | S16: =IF(R16<>"Ja","",IF($J16="",P_RAL,$J16)) | T16: =IF($B16="","",P16&" · "&Q16&" mm") | U16: =IF(R16="Ja",COUNTIF($R$6:R16,"Ja"),"") | V16: =IF($B16="","",IF(COUNTIF($B$6:$B16,$B16)=1,MAX($V$5:V15)+1,"")) | W16: =IF(T16="","",IF(COUNTIF($T$6:T16,T16)=1,MAX($W$5:W15)+1,"")) | X16: =IF($B16="","",IF($C16="","– ohne Angabe –",$C16)) | Y16: =IF(X16="","",IF(COUNTIF($X$6:X16,X16)=1,MAX($Y$5:Y15)+1,"")) | Z16: =IF($B16="","",INDEX($Y$6:$Y$205,MATCH(X16,$X$6:$X$205,0))*1000+ROW()-5) | AA16: =IF(OR($F16="",$G16="",T16=""),"",IFERROR(MAX(INT(INDEX(Tafelbedarf!$O$9:$O$48,MATCH(T16,Tafelbedarf!$A$9:$A$48,0))/$F16)*INT(INDEX(Tafelbedarf!$P$9:$P$48,MATCH(T16,Tafelbedarf!$A$9:$A$48,0))/$G16),INT(INDEX(Tafelbedarf!$P$9:$P$48,MATCH(T16,Tafelbedarf!$A$9:$A$48,0))/$F16)*INT(INDEX(Tafelbedarf!$O$9:$O$48,MATCH(T16,Tafelbedarf!$A$9:$A$48,0))/$G16)),"")) | AB16: =IF(OR(AA16="",$H16=""),"",IF(AA16=0,"",ROUNDUP($H16/AA16,0))) | AC16: =IF($B16="","",COUNTIF($B$6:$B16,"?*"))
K17: =IF(OR($G17="",$H17=""),"",$G17*$H17/1000) | L17: =IF(OR(K17="",$F17=""),"",K17*$F17/1000) | M17: =IF(OR(L17="",Q17=""),"",IFERROR(L17*Q17*INDEX(L_Dichte,MATCH(P17,L_Material,0)),"")) | P17: =IF($B17="","",IF($D17="",P_MAT,$D17)) | Q17: =IF($B17="","",IF($E17="",P_DICKE,$E17)) | R17: =IF($B17="","",IF($I17="",P_BESCH,$I17)) | S17: =IF(R17<>"Ja","",IF($J17="",P_RAL,$J17)) | T17: =IF($B17="","",P17&" · "&Q17&" mm") | U17: =IF(R17="Ja",COUNTIF($R$6:R17,"Ja"),"") | V17: =IF($B17="","",IF(COUNTIF($B$6:$B17,$B17)=1,MAX($V$5:V16)+1,"")) | W17: =IF(T17="","",IF(COUNTIF($T$6:T17,T17)=1,MAX($W$5:W16)+1,"")) | X17: =IF($B17="","",IF($C17="","– ohne Angabe –",$C17)) | Y17: =IF(X17="","",IF(COUNTIF($X$6:X17,X17)=1,MAX($Y$5:Y16)+1,"")) | Z17: =IF($B17="","",INDEX($Y$6:$Y$205,MATCH(X17,$X$6:$X$205,0))*1000+ROW()-5) | AA17: =IF(OR($F17="",$G17="",T17=""),"",IFERROR(MAX(INT(INDEX(Tafelbedarf!$O$9:$O$48,MATCH(T17,Tafelbedarf!$A$9:$A$48,0))/$F17)*INT(INDEX(Tafelbedarf!$P$9:$P$48,MATCH(T17,Tafelbedarf!$A$9:$A$48,0))/$G17),INT(INDEX(Tafelbedarf!$P$9:$P$48,MATCH(T17,Tafelbedarf!$A$9:$A$48,0))/$F17)*INT(INDEX(Tafelbedarf!$O$9:$O$48,MATCH(T17,Tafelbedarf!$A$9:$A$48,0))/$G17)),"")) | AB17: =IF(OR(AA17="",$H17=""),"",IF(AA17=0,"",ROUNDUP($H17/AA17,0))) | AC17: =IF($B17="","",COUNTIF($B$6:$B17,"?*"))
... K205: =IF(OR($G205="",$H205=""),"",$G205*$H205/1000) | L205: =IF(OR(K205="",$F205=""),"",K205*$F205/1000) | M205: =IF(OR(L205="",Q205=""),"",IFERROR(L205*Q205*INDEX(L_Dichte,MATCH(P205,L_Material,0)),"")) | P205: =IF($B205="","",IF($D205="",P_MAT,$D205)) | Q205: =IF($B205="","",IF($E205="",P_DICKE,$E205)) | R205: =IF($B205="","",IF($I205="",P_BESCH,$I205)) | S205: =IF(R205<>"Ja","",IF($J205="",P_RAL,$J205)) | T205: =IF($B205="","",P205&" · "&Q205&" mm") | U205: =IF(R205="Ja",COUNTIF($R$6:R205,"Ja"),"") | V205: =IF($B205="","",IF(COUNTIF($B$6:$B205,$B205)=1,MAX($V$5:V204)+1,"")) | W205: =IF(T205="","",IF(COUNTIF($T$6:T205,T205)=1,MAX($W$5:W204)+1,"")) | X205: =IF($B205="","",IF($C205="","– ohne Angabe –",$C205)) | Y205: =IF(X205="","",IF(COUNTIF($X$6:X205,X205)=1,MAX($Y$5:Y204)+1,"")) | Z205: =IF($B205="","",INDEX($Y$6:$Y$205,MATCH(X205,$X$6:$X$205,0))*1000+ROW()-5) | AA205: =IF(OR($F205="",$G205="",T205=""),"",IFERROR(MAX(INT(INDEX(Tafelbedarf!$O$9:$O$48,MATCH(T205,Tafelbedarf!$A$9:$A$48,0))/$F205)*INT(INDEX(Tafelbedarf!$P$9:$P$48,MATCH(T205,Tafelbedarf!$A$9:$A$48,0))/$G205),INT(INDEX(Tafelbedarf!$P$9:$P$48,MATCH(T205,Tafelbedarf!$A$9:$A$48,0))/$F205)*INT(INDEX(Tafelbedarf!$O$9:$O$48,MATCH(T205,Tafelbedarf!$A$9:$A$48,0))/$G205)),"")) | AB205: =IF(OR(AA205="",$H205=""),"",IF(AA205=0,"",ROUNDUP($H205/AA205,0))) | AC205: =IF($B205="","",COUNTIF($B$6:$B205,"?*"))

Sheet Beschichtungsauftrag
J1: 2R Metall GmbH | L1: =MAX(1,B25)
J2: Eichwiesstrasse 18a
J3: 8645 Rapperswil-Jona
J4: Telefon +41 44 521 48 48
J5: info@2r-metall.ch
A7: BESCHICHTUNGSAUFTRAG | J7: =IF(P_NR="","","Kommission "&P_NR)
A10: An | B10: =IF(P_BESCHICHTER="","",P_BESCHICHTER) | F10: Datum | H10: =IF(P_DATUM="","",P_DATUM)
A11: Kommission | B11: =IF(P_NR="","",P_NR&" · "&P_NAME) | F11: Kontakt 2R | H11: =IF(P_PL="",IF(P_BEARBEITER="","",P_BEARBEITER),P_PL)
A12: Baustelle | B12: =IF(P_ADRESSE="","",P_ADRESSE) | F12: Liefertermin | H12: =IF(P_TERMIN="","nach Vereinbarung",P_TERMIN)
A14: Farbe / RAL | D14: Glanzgrad | F14: Struktur | H14: Seite | J14: Lieferung
A15: =IF(P_RAL="","",P_RAL) | D15: =IF(P_GLANZ="","",P_GLANZ) | F15: =IF(P_STRUKTUR="","",P_STRUKTUR) | H15: =IF(P_SEITE="","",P_SEITE) | J15: =IF(P_LIEFERUNG="","",P_LIEFERUNG)
A16: =IF(P_QUALI="","","Qualität / Norm: "&P_QUALI)
A18: BEMERKUNG / NOTIZ / SKIZZE
A25: Positionen | B25: =COUNT(Positionen!$U$6:$U$205) | C25: Total Stück | D25: =SUMIFS(Positionen!$H$6:$H$205,Positionen!$R$6:$R$205,"Ja") | E25: Total m² | F25: =SUMIFS(Positionen!$L$6:$L$205,Positionen!$R$6:$R$205,"Ja") | G25: Total lfm | H25: =SUMIFS(Positionen!$K$6:$K$205,Positionen!$R$6:$R$205,"Ja")
A26: Bitte Auftragsbestätigung mit Liefertermin per E-Mail an info@2r-metall.ch. Spezialfarben mit Preisaufschlag bitte vorgängig per E-Mail mitteilen. Preise ohne Lieferung / Abholung. Teile mit Pos.-Nr. und Kommission beschriften.
A29: Pos. | B29: Bauteil | C29: Material | D29: Dicke mm | E29: Abwicklung mm | F29: Länge mm | G29: Anzahl Stk | H29: m² | I29: Farbe / RAL | J29: Bemerkung
A30: =IF(B30="","",INDEX(Positionen!$A$6:$A$205,MATCH(1,Positionen!$U$6:$U$205,0))&"") | B30: =IFERROR(INDEX(Positionen!$B$6:$B$205,MATCH(1,Positionen!$U$6:$U$205,0)),"") | C30: =IF(B30="","",INDEX(Positionen!$P$6:$P$205,MATCH(1,Positionen!$U$6:$U$205,0))) | D30: =IF(B30="","",INDEX(Positionen!$Q$6:$Q$205,MATCH(1,Positionen!$U$6:$U$205,0))) | E30: =IF(B30="","",IF(INDEX(Positionen!$F$6:$F$205,MATCH(1,Positionen!$U$6:$U$205,0))="","",INDEX(Positionen!$F$6:$F$205,MATCH(1,Positionen!$U$6:$U$205,0)))) | F30: =IF(B30="","",IF(INDEX(Positionen!$G$6:$G$205,MATCH(1,Positionen!$U$6:$U$205,0))="","",INDEX(Positionen!$G$6:$G$205,MATCH(1,Positionen!$U$6:$U$205,0)))) | G30: =IF(B30="","",IF(INDEX(Positionen!$H$6:$H$205,MATCH(1,Positionen!$U$6:$U$205,0))="","",INDEX(Positionen!$H$6:$H$205,MATCH(1,Positionen!$U$6:$U$205,0)))) | H30: =IF(B30="","",INDEX(Positionen!$L$6:$L$205,MATCH(1,Positionen!$U$6:$U$205,0))) | I30: =IF(B30="","",INDEX(Positionen!$S$6:$S$205,MATCH(1,Positionen!$U$6:$U$205,0))) | J30: =IF(B30="","",IF(INDEX(Positionen!$N$6:$N$205,MATCH(1,Positionen!$U$6:$U$205,0))="","",INDEX(Positionen!$N$6:$N$205,MATCH(1,Positionen!$U$6:$U$205,0))))
A31: =IF(B31="","",INDEX(Positionen!$A$6:$A$205,MATCH(2,Positionen!$U$6:$U$205,0))&"") | B31: =IFERROR(INDEX(Positionen!$B$6:$B$205,MATCH(2,Positionen!$U$6:$U$205,0)),"") | C31: =IF(B31="","",INDEX(Positionen!$P$6:$P$205,MATCH(2,Positionen!$U$6:$U$205,0))) | D31: =IF(B31="","",INDEX(Positionen!$Q$6:$Q$205,MATCH(2,Positionen!$U$6:$U$205,0))) | E31: =IF(B31="","",IF(INDEX(Positionen!$F$6:$F$205,MATCH(2,Positionen!$U$6:$U$205,0))="","",INDEX(Positionen!$F$6:$F$205,MATCH(2,Positionen!$U$6:$U$205,0)))) | F31: =IF(B31="","",IF(INDEX(Positionen!$G$6:$G$205,MATCH(2,Positionen!$U$6:$U$205,0))="","",INDEX(Positionen!$G$6:$G$205,MATCH(2,Positionen!$U$6:$U$205,0)))) | G31: =IF(B31="","",IF(INDEX(Positionen!$H$6:$H$205,MATCH(2,Positionen!$U$6:$U$205,0))="","",INDEX(Positionen!$H$6:$H$205,MATCH(2,Positionen!$U$6:$U$205,0)))) | H31: =IF(B31="","",INDEX(Positionen!$L$6:$L$205,MATCH(2,Positionen!$U$6:$U$205,0))) | I31: =IF(B31="","",INDEX(Positionen!$S$6:$S$205,MATCH(2,Positionen!$U$6:$U$205,0))) | J31: =IF(B31="","",IF(INDEX(Positionen!$N$6:$N$205,MATCH(2,Positionen!$U$6:$U$205,0))="","",INDEX(Positionen!$N$6:$N$205,MATCH(2,Positionen!$U$6:$U$205,0))))
A32: =IF(B32="","",INDEX(Positionen!$A$6:$A$205,MATCH(3,Positionen!$U$6:$U$205,0))&"") | B32: =IFERROR(INDEX(Positionen!$B$6:$B$205,MATCH(3,Positionen!$U$6:$U$205,0)),"") | C32: =IF(B32="","",INDEX(Positionen!$P$6:$P$205,MATCH(3,Positionen!$U$6:$U$205,0))) | D32: =IF(B32="","",INDEX(Positionen!$Q$6:$Q$205,MATCH(3,Positionen!$U$6:$U$205,0))) | E32: =IF(B32="","",IF(INDEX(Positionen!$F$6:$F$205,MATCH(3,Positionen!$U$6:$U$205,0))="","",INDEX(Positionen!$F$6:$F$205,MATCH(3,Positionen!$U$6:$U$205,0)))) | F32: =IF(B32="","",IF(INDEX(Positionen!$G$6:$G$205,MATCH(3,Positionen!$U$6:$U$205,0))="","",INDEX(Positionen!$G$6:$G$205,MATCH(3,Positionen!$U$6:$U$205,0)))) | G32: =IF(B32="","",IF(INDEX(Positionen!$H$6:$H$205,MATCH(3,Positionen!$U$6:$U$205,0))="","",INDEX(Positionen!$H$6:$H$205,MATCH(3,Positionen!$U$6:$U$205,0)))) | H32: =IF(B32="","",INDEX(Positionen!$L$6:$L$205,MATCH(3,Positionen!$U$6:$U$205,0))) | I32: =IF(B32="","",INDEX(Positionen!$S$6:$S$205,MATCH(3,Positionen!$U$6:$U$205,0))) | J32: =IF(B32="","",IF(INDEX(Positionen!$N$6:$N$205,MATCH(3,Positionen!$U$6:$U$205,0))="","",INDEX(Positionen!$N$6:$N$205,MATCH(3,Positionen!$U$6:$U$205,0))))
A33: =IF(B33="","",INDEX(Positionen!$A$6:$A$205,MATCH(4,Positionen!$U$6:$U$205,0))&"") | B33: =IFERROR(INDEX(Positionen!$B$6:$B$205,MATCH(4,Positionen!$U$6:$U$205,0)),"") | C33: =IF(B33="","",INDEX(Positionen!$P$6:$P$205,MATCH(4,Positionen!$U$6:$U$205,0))) | D33: =IF(B33="","",INDEX(Positionen!$Q$6:$Q$205,MATCH(4,Positionen!$U$6:$U$205,0))) | E33: =IF(B33="","",IF(INDEX(Positionen!$F$6:$F$205,MATCH(4,Positionen!$U$6:$U$205,0))="","",INDEX(Positionen!$F$6:$F$205,MATCH(4,Positionen!$U$6:$U$205,0)))) | F33: =IF(B33="","",IF(INDEX(Positionen!$G$6:$G$205,MATCH(4,Positionen!$U$6:$U$205,0))="","",INDEX(Positionen!$G$6:$G$205,MATCH(4,Positionen!$U$6:$U$205,0)))) | G33: =IF(B33="","",IF(INDEX(Positionen!$H$6:$H$205,MATCH(4,Positionen!$U$6:$U$205,0))="","",INDEX(Positionen!$H$6:$H$205,MATCH(4,Positionen!$U$6:$U$205,0)))) | H33: =IF(B33="","",INDEX(Positionen!$L$6:$L$205,MATCH(4,Positionen!$U$6:$U$205,0))) | I33: =IF(B33="","",INDEX(Positionen!$S$6:$S$205,MATCH(4,Positionen!$U$6:$U$205,0))) | J33: =IF(B33="","",IF(INDEX(Positionen!$N$6:$N$205,MATCH(4,Positionen!$U$6:$U$205,0))="","",INDEX(Positionen!$N$6:$N$205,MATCH(4,Positionen!$U$6:$U$205,0))))
A34: =IF(B34="","",INDEX(Positionen!$A$6:$A$205,MATCH(5,Positionen!$U$6:$U$205,0))&"") | B34: =IFERROR(INDEX(Positionen!$B$6:$B$205,MATCH(5,Positionen!$U$6:$U$205,0)),"") | C34: =IF(B34="","",INDEX(Positionen!$P$6:$P$205,MATCH(5,Positionen!$U$6:$U$205,0))) | D34: =IF(B34="","",INDEX(Positionen!$Q$6:$Q$205,MATCH(5,Positionen!$U$6:$U$205,0))) | E34: =IF(B34="","",IF(INDEX(Positionen!$F$6:$F$205,MATCH(5,Positionen!$U$6:$U$205,0))="","",INDEX(Positionen!$F$6:$F$205,MATCH(5,Positionen!$U$6:$U$205,0)))) | F34: =IF(B34="","",IF(INDEX(Positionen!$G$6:$G$205,MATCH(5,Positionen!$U$6:$U$205,0))="","",INDEX(Positionen!$G$6:$G$205,MATCH(5,Positionen!$U$6:$U$205,0)))) | G34: =IF(B34="","",IF(INDEX(Positionen!$H$6:$H$205,MATCH(5,Positionen!$U$6:$U$205,0))="","",INDEX(Positionen!$H$6:$H$205,MATCH(5,Positionen!$U$6:$U$205,0)))) | H34: =IF(B34="","",INDEX(Positionen!$L$6:$L$205,MATCH(5,Positionen!$U$6:$U$205,0))) | I34: =IF(B34="","",INDEX(Positionen!$S$6:$S$205,MATCH(5,Positionen!$U$6:$U$205,0))) | J34: =IF(B34="","",IF(INDEX(Positionen!$N$6:$N$205,MATCH(5,Positionen!$U$6:$U$205,0))="","",INDEX(Positionen!$N$6:$N$205,MATCH(5,Positionen!$U$6:$U$205,0))))
A35: =IF(B35="","",INDEX(Positionen!$A$6:$A$205,MATCH(6,Positionen!$U$6:$U$205,0))&"") | B35: =IFERROR(INDEX(Positionen!$B$6:$B$205,MATCH(6,Positionen!$U$6:$U$205,0)),"") | C35: =IF(B35="","",INDEX(Positionen!$P$6:$P$205,MATCH(6,Positionen!$U$6:$U$205,0))) | D35: =IF(B35="","",INDEX(Positionen!$Q$6:$Q$205,MATCH(6,Positionen!$U$6:$U$205,0))) | E35: =IF(B35="","",IF(INDEX(Positionen!$F$6:$F$205,MATCH(6,Positionen!$U$6:$U$205,0))="","",INDEX(Positionen!$F$6:$F$205,MATCH(6,Positionen!$U$6:$U$205,0)))) | F35: =IF(B35="","",IF(INDEX(Positionen!$G$6:$G$205,MATCH(6,Positionen!$U$6:$U$205,0))="","",INDEX(Positionen!$G$6:$G$205,MATCH(6,Positionen!$U$6:$U$205,0)))) | G35: =IF(B35="","",IF(INDEX(Positionen!$H$6:$H$205,MATCH(6,Positionen!$U$6:$U$205,0))="","",INDEX(Positionen!$H$6:$H$205,MATCH(6,Positionen!$U$6:$U$205,0)))) | H35: =IF(B35="","",INDEX(Positionen!$L$6:$L$205,MATCH(6,Positionen!$U$6:$U$205,0))) | I35: =IF(B35="","",INDEX(Positionen!$S$6:$S$205,MATCH(6,Positionen!$U$6:$U$205,0))) | J35: =IF(B35="","",IF(INDEX(Positionen!$N$6:$N$205,MATCH(6,Positionen!$U$6:$U$205,0))="","",INDEX(Positionen!$N$6:$N$205,MATCH(6,Positionen!$U$6:$U$205,0))))
A36: =IF(B36="","",INDEX(Positionen!$A$6:$A$205,MATCH(7,Positionen!$U$6:$U$205,0))&"") | B36: =IFERROR(INDEX(Positionen!$B$6:$B$205,MATCH(7,Positionen!$U$6:$U$205,0)),"") | C36: =IF(B36="","",INDEX(Positionen!$P$6:$P$205,MATCH(7,Positionen!$U$6:$U$205,0))) | D36: =IF(B36="","",INDEX(Positionen!$Q$6:$Q$205,MATCH(7,Positionen!$U$6:$U$205,0))) | E36: =IF(B36="","",IF(INDEX(Positionen!$F$6:$F$205,MATCH(7,Positionen!$U$6:$U$205,0))="","",INDEX(Positionen!$F$6:$F$205,MATCH(7,Positionen!$U$6:$U$205,0)))) | F36: =IF(B36="","",IF(INDEX(Positionen!$G$6:$G$205,MATCH(7,Positionen!$U$6:$U$205,0))="","",INDEX(Positionen!$G$6:$G$205,MATCH(7,Positionen!$U$6:$U$205,0)))) | G36: =IF(B36="","",IF(INDEX(Positionen!$H$6:$H$205,MATCH(7,Positionen!$U$6:$U$205,0))="","",INDEX(Positionen!$H$6:$H$205,MATCH(7,Positionen!$U$6:$U$205,0)))) | H36: =IF(B36="","",INDEX(Positionen!$L$6:$L$205,MATCH(7,Positionen!$U$6:$U$205,0))) | I36: =IF(B36="","",INDEX(Positionen!$S$6:$S$205,MATCH(7,Positionen!$U$6:$U$205,0))) | J36: =IF(B36="","",IF(INDEX(Positionen!$N$6:$N$205,MATCH(7,Positionen!$U$6:$U$205,0))="","",INDEX(Positionen!$N$6:$N$205,MATCH(7,Positionen!$U$6:$U$205,0))))
A37: =IF(B37="","",INDEX(Positionen!$A$6:$A$205,MATCH(8,Positionen!$U$6:$U$205,0))&"") | B37: =IFERROR(INDEX(Positionen!$B$6:$B$205,MATCH(8,Positionen!$U$6:$U$205,0)),"") | C37: =IF(B37="","",INDEX(Positionen!$P$6:$P$205,MATCH(8,Positionen!$U$6:$U$205,0))) | D37: =IF(B37="","",INDEX(Positionen!$Q$6:$Q$205,MATCH(8,Positionen!$U$6:$U$205,0))) | E37: =IF(B37="","",IF(INDEX(Positionen!$F$6:$F$205,MATCH(8,Positionen!$U$6:$U$205,0))="","",INDEX(Positionen!$F$6:$F$205,MATCH(8,Positionen!$U$6:$U$205,0)))) | F37: =IF(B37="","",IF(INDEX(Positionen!$G$6:$G$205,MATCH(8,Positionen!$U$6:$U$205,0))="","",INDEX(Positionen!$G$6:$G$205,MATCH(8,Positionen!$U$6:$U$205,0)))) | G37: =IF(B37="","",IF(INDEX(Positionen!$H$6:$H$205,MATCH(8,Positionen!$U$6:$U$205,0))="","",INDEX(Positionen!$H$6:$H$205,MATCH(8,Positionen!$U$6:$U$205,0)))) | H37: =IF(B37="","",INDEX(Positionen!$L$6:$L$205,MATCH(8,Positionen!$U$6:$U$205,0))) | I37: =IF(B37="","",INDEX(Positionen!$S$6:$S$205,MATCH(8,Positionen!$U$6:$U$205,0))) | J37: =IF(B37="","",IF(INDEX(Positionen!$N$6:$N$205,MATCH(8,Positionen!$U$6:$U$205,0))="","",INDEX(Positionen!$N$6:$N$205,MATCH(8,Positionen!$U$6:$U$205,0))))
A38: =IF(B38="","",INDEX(Positionen!$A$6:$A$205,MATCH(9,Positionen!$U$6:$U$205,0))&"") | B38: =IFERROR(INDEX(Positionen!$B$6:$B$205,MATCH(9,Positionen!$U$6:$U$205,0)),"") | C38: =IF(B38="","",INDEX(Positionen!$P$6:$P$205,MATCH(9,Positionen!$U$6:$U$205,0))) | D38: =IF(B38="","",INDEX(Positionen!$Q$6:$Q$205,MATCH(9,Positionen!$U$6:$U$205,0))) | E38: =IF(B38="","",IF(INDEX(Positionen!$F$6:$F$205,MATCH(9,Positionen!$U$6:$U$205,0))="","",INDEX(Positionen!$F$6:$F$205,MATCH(9,Positionen!$U$6:$U$205,0)))) | F38: =IF(B38="","",IF(INDEX(Positionen!$G$6:$G$205,MATCH(9,Positionen!$U$6:$U$205,0))="","",INDEX(Positionen!$G$6:$G$205,MATCH(9,Positionen!$U$6:$U$205,0)))) | G38: =IF(B38="","",IF(INDEX(Positionen!$H$6:$H$205,MATCH(9,Positionen!$U$6:$U$205,0))="","",INDEX(Positionen!$H$6:$H$205,MATCH(9,Positionen!$U$6:$U$205,0)))) | H38: =IF(B38="","",INDEX(Positionen!$L$6:$L$205,MATCH(9,Positionen!$U$6:$U$205,0))) | I38: =IF(B38="","",INDEX(Positionen!$S$6:$S$205,MATCH(9,Positionen!$U$6:$U$205,0))) | J38: =IF(B38="","",IF(INDEX(Positionen!$N$6:$N$205,MATCH(9,Positionen!$U$6:$U$205,0))="","",INDEX(Positionen!$N$6:$N$205,MATCH(9,Positionen!$U$6:$U$205,0))))
A39: =IF(B39="","",INDEX(Positionen!$A$6:$A$205,MATCH(10,Positionen!$U$6:$U$205,0))&"") | B39: =IFERROR(INDEX(Positionen!$B$6:$B$205,MATCH(10,Positionen!$U$6:$U$205,0)),"") | C39: =IF(B39="","",INDEX(Positionen!$P$6:$P$205,MATCH(10,Positionen!$U$6:$U$205,0))) | D39: =IF(B39="","",INDEX(Positionen!$Q$6:$Q$205,MATCH(10,Positionen!$U$6:$U$205,0))) | E39: =IF(B39="","",IF(INDEX(Positionen!$F$6:$F$205,MATCH(10,Positionen!$U$6:$U$205,0))="","",INDEX(Positionen!$F$6:$F$205,MATCH(10,Positionen!$U$6:$U$205,0)))) | F39: =IF(B39="","",IF(INDEX(Positionen!$G$6:$G$205,MATCH(10,Positionen!$U$6:$U$205,0))="","",INDEX(Positionen!$G$6:$G$205,MATCH(10,Positionen!$U$6:$U$205,0)))) | G39: =IF(B39="","",IF(INDEX(Positionen!$H$6:$H$205,MATCH(10,Positionen!$U$6:$U$205,0))="","",INDEX(Positionen!$H$6:$H$205,MATCH(10,Positionen!$U$6:$U$205,0)))) | H39: =IF(B39="","",INDEX(Positionen!$L$6:$L$205,MATCH(10,Positionen!$U$6:$U$205,0))) | I39: =IF(B39="","",INDEX(Positionen!$S$6:$S$205,MATCH(10,Positionen!$U$6:$U$205,0))) | J39: =IF(B39="","",IF(INDEX(Positionen!$N$6:$N$205,MATCH(10,Positionen!$U$6:$U$205,0))="","",INDEX(Positionen!$N$6:$N$205,MATCH(10,Positionen!$U$6:$U$205,0))))
A40: =IF(B40="","",INDEX(Positionen!$A$6:$A$205,MATCH(11,Positionen!$U$6:$U$205,0))&"") | B40: =IFERROR(INDEX(Positionen!$B$6:$B$205,MATCH(11,Positionen!$U$6:$U$205,0)),"") | C40: =IF(B40="","",INDEX(Positionen!$P$6:$P$205,MATCH(11,Positionen!$U$6:$U$205,0))) | D40: =IF(B40="","",INDEX(Positionen!$Q$6:$Q$205,MATCH(11,Positionen!$U$6:$U$205,0))) | E40: =IF(B40="","",IF(INDEX(Positionen!$F$6:$F$205,MATCH(11,Positionen!$U$6:$U$205,0))="","",INDEX(Positionen!$F$6:$F$205,MATCH(11,Positionen!$U$6:$U$205,0)))) | F40: =IF(B40="","",IF(INDEX(Positionen!$G$6:$G$205,MATCH(11,Positionen!$U$6:$U$205,0))="","",INDEX(Positionen!$G$6:$G$205,MATCH(11,Positionen!$U$6:$U$205,0)))) | G40: =IF(B40="","",IF(INDEX(Positionen!$H$6:$H$205,MATCH(11,Positionen!$U$6:$U$205,0))="","",INDEX(Positionen!$H$6:$H$205,MATCH(11,Positionen!$U$6:$U$205,0)))) | H40: =IF(B40="","",INDEX(Positionen!$L$6:$L$205,MATCH(11,Positionen!$U$6:$U$205,0))) | I40: =IF(B40="","",INDEX(Positionen!$S$6:$S$205,MATCH(11,Positionen!$U$6:$U$205,0))) | J40: =IF(B40="","",IF(INDEX(Positionen!$N$6:$N$205,MATCH(11,Positionen!$U$6:$U$205,0))="","",INDEX(Positionen!$N$6:$N$205,MATCH(11,Positionen!$U$6:$U$205,0))))
A41: =IF(B41="","",INDEX(Positionen!$A$6:$A$205,MATCH(12,Positionen!$U$6:$U$205,0))&"") | B41: =IFERROR(INDEX(Positionen!$B$6:$B$205,MATCH(12,Positionen!$U$6:$U$205,0)),"") | C41: =IF(B41="","",INDEX(Positionen!$P$6:$P$205,MATCH(12,Positionen!$U$6:$U$205,0))) | D41: =IF(B41="","",INDEX(Positionen!$Q$6:$Q$205,MATCH(12,Positionen!$U$6:$U$205,0))) | E41: =IF(B41="","",IF(INDEX(Positionen!$F$6:$F$205,MATCH(12,Positionen!$U$6:$U$205,0))="","",INDEX(Positionen!$F$6:$F$205,MATCH(12,Positionen!$U$6:$U$205,0)))) | F41: =IF(B41="","",IF(INDEX(Positionen!$G$6:$G$205,MATCH(12,Positionen!$U$6:$U$205,0))="","",INDEX(Positionen!$G$6:$G$205,MATCH(12,Positionen!$U$6:$U$205,0)))) | G41: =IF(B41="","",IF(INDEX(Positionen!$H$6:$H$205,MATCH(12,Positionen!$U$6:$U$205,0))="","",INDEX(Positionen!$H$6:$H$205,MATCH(12,Positionen!$U$6:$U$205,0)))) | H41: =IF(B41="","",INDEX(Positionen!$L$6:$L$205,MATCH(12,Positionen!$U$6:$U$205,0))) | I41: =IF(B41="","",INDEX(Positionen!$S$6:$S$205,MATCH(12,Positionen!$U$6:$U$205,0))) | J41: =IF(B41="","",IF(INDEX(Positionen!$N$6:$N$205,MATCH(12,Positionen!$U$6:$U$205,0))="","",INDEX(Positionen!$N$6:$N$205,MATCH(12,Positionen!$U$6:$U$205,0))))
A42: =IF(B42="","",INDEX(Positionen!$A$6:$A$205,MATCH(13,Positionen!$U$6:$U$205,0))&"") | B42: =IFERROR(INDEX(Positionen!$B$6:$B$205,MATCH(13,Positionen!$U$6:$U$205,0)),"") | C42: =IF(B42="","",INDEX(Positionen!$P$6:$P$205,MATCH(13,Positionen!$U$6:$U$205,0))) | D42: =IF(B42="","",INDEX(Positionen!$Q$6:$Q$205,MATCH(13,Positionen!$U$6:$U$205,0))) | E42: =IF(B42="","",IF(INDEX(Positionen!$F$6:$F$205,MATCH(13,Positionen!$U$6:$U$205,0))="","",INDEX(Positionen!$F$6:$F$205,MATCH(13,Positionen!$U$6:$U$205,0)))) | F42: =IF(B42="","",IF(INDEX(Positionen!$G$6:$G$205,MATCH(13,Positionen!$U$6:$U$205,0))="","",INDEX(Positionen!$G$6:$G$205,MATCH(13,Positionen!$U$6:$U$205,0)))) | G42: =IF(B42="","",IF(INDEX(Positionen!$H$6:$H$205,MATCH(13,Positionen!$U$6:$U$205,0))="","",INDEX(Positionen!$H$6:$H$205,MATCH(13,Positionen!$U$6:$U$205,0)))) | H42: =IF(B42="","",INDEX(Positionen!$L$6:$L$205,MATCH(13,Positionen!$U$6:$U$205,0))) | I42: =IF(B42="","",INDEX(Positionen!$S$6:$S$205,MATCH(13,Positionen!$U$6:$U$205,0))) | J42: =IF(B42="","",IF(INDEX(Positionen!$N$6:$N$205,MATCH(13,Positionen!$U$6:$U$205,0))="","",INDEX(Positionen!$N$6:$N$205,MATCH(13,Positionen!$U$6:$U$205,0))))
A43: =IF(B43="","",INDEX(Positionen!$A$6:$A$205,MATCH(14,Positionen!$U$6:$U$205,0))&"") | B43: =IFERROR(INDEX(Positionen!$B$6:$B$205,MATCH(14,Positionen!$U$6:$U$205,0)),"") | C43: =IF(B43="","",INDEX(Positionen!$P$6:$P$205,MATCH(14,Positionen!$U$6:$U$205,0))) | D43: =IF(B43="","",INDEX(Positionen!$Q$6:$Q$205,MATCH(14,Positionen!$U$6:$U$205,0))) | E43: =IF(B43="","",IF(INDEX(Positionen!$F$6:$F$205,MATCH(14,Positionen!$U$6:$U$205,0))="","",INDEX(Positionen!$F$6:$F$205,MATCH(14,Positionen!$U$6:$U$205,0)))) | F43: =IF(B43="","",IF(INDEX(Positionen!$G$6:$G$205,MATCH(14,Positionen!$U$6:$U$205,0))="","",INDEX(Positionen!$G$6:$G$205,MATCH(14,Positionen!$U$6:$U$205,0)))) | G43: =IF(B43="","",IF(INDEX(Positionen!$H$6:$H$205,MATCH(14,Positionen!$U$6:$U$205,0))="","",INDEX(Positionen!$H$6:$H$205,MATCH(14,Positionen!$U$6:$U$205,0)))) | H43: =IF(B43="","",INDEX(Positionen!$L$6:$L$205,MATCH(14,Positionen!$U$6:$U$205,0))) | I43: =IF(B43="","",INDEX(Positionen!$S$6:$S$205,MATCH(14,Positionen!$U$6:$U$205,0))) | J43: =IF(B43="","",IF(INDEX(Positionen!$N$6:$N$205,MATCH(14,Positionen!$U$6:$U$205,0))="","",INDEX(Positionen!$N$6:$N$205,MATCH(14,Positionen!$U$6:$U$205,0))))
A44: =IF(B44="","",INDEX(Positionen!$A$6:$A$205,MATCH(15,Positionen!$U$6:$U$205,0))&"") | B44: =IFERROR(INDEX(Positionen!$B$6:$B$205,MATCH(15,Positionen!$U$6:$U$205,0)),"") | C44: =IF(B44="","",INDEX(Positionen!$P$6:$P$205,MATCH(15,Positionen!$U$6:$U$205,0))) | D44: =IF(B44="","",INDEX(Positionen!$Q$6:$Q$205,MATCH(15,Positionen!$U$6:$U$205,0))) | E44: =IF(B44="","",IF(INDEX(Positionen!$F$6:$F$205,MATCH(15,Positionen!$U$6:$U$205,0))="","",INDEX(Positionen!$F$6:$F$205,MATCH(15,Positionen!$U$6:$U$205,0)))) | F44: =IF(B44="","",IF(INDEX(Positionen!$G$6:$G$205,MATCH(15,Positionen!$U$6:$U$205,0))="","",INDEX(Positionen!$G$6:$G$205,MATCH(15,Positionen!$U$6:$U$205,0)))) | G44: =IF(B44="","",IF(INDEX(Positionen!$H$6:$H$205,MATCH(15,Positionen!$U$6:$U$205,0))="","",INDEX(Positionen!$H$6:$H$205,MATCH(15,Positionen!$U$6:$U$205,0)))) | H44: =IF(B44="","",INDEX(Positionen!$L$6:$L$205,MATCH(15,Positionen!$U$6:$U$205,0))) | I44: =IF(B44="","",INDEX(Positionen!$S$6:$S$205,MATCH(15,Positionen!$U$6:$U$205,0))) | J44: =IF(B44="","",IF(INDEX(Positionen!$N$6:$N$205,MATCH(15,Positionen!$U$6:$U$205,0))="","",INDEX(Positionen!$N$6:$N$205,MATCH(15,Positionen!$U$6:$U$205,0))))
A45: =IF(B45="","",INDEX(Positionen!$A$6:$A$205,MATCH(16,Positionen!$U$6:$U$205,0))&"") | B45: =IFERROR(INDEX(Positionen!$B$6:$B$205,MATCH(16,Positionen!$U$6:$U$205,0)),"") | C45: =IF(B45="","",INDEX(Positionen!$P$6:$P$205,MATCH(16,Positionen!$U$6:$U$205,0))) | D45: =IF(B45="","",INDEX(Positionen!$Q$6:$Q$205,MATCH(16,Positionen!$U$6:$U$205,0))) | E45: =IF(B45="","",IF(INDEX(Positionen!$F$6:$F$205,MATCH(16,Positionen!$U$6:$U$205,0))="","",INDEX(Positionen!$F$6:$F$205,MATCH(16,Positionen!$U$6:$U$205,0)))) | F45: =IF(B45="","",IF(INDEX(Positionen!$G$6:$G$205,MATCH(16,Positionen!$U$6:$U$205,0))="","",INDEX(Positionen!$G$6:$G$205,MATCH(16,Positionen!$U$6:$U$205,0)))) | G45: =IF(B45="","",IF(INDEX(Positionen!$H$6:$H$205,MATCH(16,Positionen!$U$6:$U$205,0))="","",INDEX(Positionen!$H$6:$H$205,MATCH(16,Positionen!$U$6:$U$205,0)))) | H45: =IF(B45="","",INDEX(Positionen!$L$6:$L$205,MATCH(16,Positionen!$U$6:$U$205,0))) | I45: =IF(B45="","",INDEX(Positionen!$S$6:$S$205,MATCH(16,Positionen!$U$6:$U$205,0))) | J45: =IF(B45="","",IF(INDEX(Positionen!$N$6:$N$205,MATCH(16,Positionen!$U$6:$U$205,0))="","",INDEX(Positionen!$N$6:$N$205,MATCH(16,Positionen!$U$6:$U$205,0))))
A46: =IF(B46="","",INDEX(Positionen!$A$6:$A$205,MATCH(17,Positionen!$U$6:$U$205,0))&"") | B46: =IFERROR(INDEX(Positionen!$B$6:$B$205,MATCH(17,Positionen!$U$6:$U$205,0)),"") | C46: =IF(B46="","",INDEX(Positionen!$P$6:$P$205,MATCH(17,Positionen!$U$6:$U$205,0))) | D46: =IF(B46="","",INDEX(Positionen!$Q$6:$Q$205,MATCH(17,Positionen!$U$6:$U$205,0))) | E46: =IF(B46="","",IF(INDEX(Positionen!$F$6:$F$205,MATCH(17,Positionen!$U$6:$U$205,0))="","",INDEX(Positionen!$F$6:$F$205,MATCH(17,Positionen!$U$6:$U$205,0)))) | F46: =IF(B46="","",IF(INDEX(Positionen!$G$6:$G$205,MATCH(17,Positionen!$U$6:$U$205,0))="","",INDEX(Positionen!$G$6:$G$205,MATCH(17,Positionen!$U$6:$U$205,0)))) | G46: =IF(B46="","",IF(INDEX(Positionen!$H$6:$H$205,MATCH(17,Positionen!$U$6:$U$205,0))="","",INDEX(Positionen!$H$6:$H$205,MATCH(17,Positionen!$U$6:$U$205,0)))) | H46: =IF(B46="","",INDEX(Positionen!$L$6:$L$205,MATCH(17,Positionen!$U$6:$U$205,0))) | I46: =IF(B46="","",INDEX(Positionen!$S$6:$S$205,MATCH(17,Positionen!$U$6:$U$205,0))) | J46: =IF(B46="","",IF(INDEX(Positionen!$N$6:$N$205,MATCH(17,Positionen!$U$6:$U$205,0))="","",INDEX(Positionen!$N$6:$N$205,MATCH(17,Positionen!$U$6:$U$205,0))))
A47: =IF(B47="","",INDEX(Positionen!$A$6:$A$205,MATCH(18,Positionen!$U$6:$U$205,0))&"") | B47: =IFERROR(INDEX(Positionen!$B$6:$B$205,MATCH(18,Positionen!$U$6:$U$205,0)),"") | C47: =IF(B47="","",INDEX(Positionen!$P$6:$P$205,MATCH(18,Positionen!$U$6:$U$205,0))) | D47: =IF(B47="","",INDEX(Positionen!$Q$6:$Q$205,MATCH(18,Positionen!$U$6:$U$205,0))) | E47: =IF(B47="","",IF(INDEX(Positionen!$F$6:$F$205,MATCH(18,Positionen!$U$6:$U$205,0))="","",INDEX(Positionen!$F$6:$F$205,MATCH(18,Positionen!$U$6:$U$205,0)))) | F47: =IF(B47="","",IF(INDEX(Positionen!$G$6:$G$205,MATCH(18,Positionen!$U$6:$U$205,0))="","",INDEX(Positionen!$G$6:$G$205,MATCH(18,Positionen!$U$6:$U$205,0)))) | G47: =IF(B47="","",IF(INDEX(Positionen!$H$6:$H$205,MATCH(18,Positionen!$U$6:$U$205,0))="","",INDEX(Positionen!$H$6:$H$205,MATCH(18,Positionen!$U$6:$U$205,0)))) | H47: =IF(B47="","",INDEX(Positionen!$L$6:$L$205,MATCH(18,Positionen!$U$6:$U$205,0))) | I47: =IF(B47="","",INDEX(Positionen!$S$6:$S$205,MATCH(18,Positionen!$U$6:$U$205,0))) | J47: =IF(B47="","",IF(INDEX(Positionen!$N$6:$N$205,MATCH(18,Positionen!$U$6:$U$205,0))="","",INDEX(Positionen!$N$6:$N$205,MATCH(18,Positionen!$U$6:$U$205,0))))
A48: =IF(B48="","",INDEX(Positionen!$A$6:$A$205,MATCH(19,Positionen!$U$6:$U$205,0))&"") | B48: =IFERROR(INDEX(Positionen!$B$6:$B$205,MATCH(19,Positionen!$U$6:$U$205,0)),"") | C48: =IF(B48="","",INDEX(Positionen!$P$6:$P$205,MATCH(19,Positionen!$U$6:$U$205,0))) | D48: =IF(B48="","",INDEX(Positionen!$Q$6:$Q$205,MATCH(19,Positionen!$U$6:$U$205,0))) | E48: =IF(B48="","",IF(INDEX(Positionen!$F$6:$F$205,MATCH(19,Positionen!$U$6:$U$205,0))="","",INDEX(Positionen!$F$6:$F$205,MATCH(19,Positionen!$U$6:$U$205,0)))) | F48: =IF(B48="","",IF(INDEX(Positionen!$G$6:$G$205,MATCH(19,Positionen!$U$6:$U$205,0))="","",INDEX(Positionen!$G$6:$G$205,MATCH(19,Positionen!$U$6:$U$205,0)))) | G48: =IF(B48="","",IF(INDEX(Positionen!$H$6:$H$205,MATCH(19,Positionen!$U$6:$U$205,0))="","",INDEX(Positionen!$H$6:$H$205,MATCH(19,Positionen!$U$6:$U$205,0)))) | H48: =IF(B48="","",INDEX(Positionen!$L$6:$L$205,MATCH(19,Positionen!$U$6:$U$205,0))) | I48: =IF(B48="","",INDEX(Positionen!$S$6:$S$205,MATCH(19,Positionen!$U$6:$U$205,0))) | J48: =IF(B48="","",IF(INDEX(Positionen!$N$6:$N$205,MATCH(19,Positionen!$U$6:$U$205,0))="","",INDEX(Positionen!$N$6:$N$205,MATCH(19,Positionen!$U$6:$U$205,0))))
A49: =IF(B49="","",INDEX(Positionen!$A$6:$A$205,MATCH(20,Positionen!$U$6:$U$205,0))&"") | B49: =IFERROR(INDEX(Positionen!$B$6:$B$205,MATCH(20,Positionen!$U$6:$U$205,0)),"") | C49: =IF(B49="","",INDEX(Positionen!$P$6:$P$205,MATCH(20,Positionen!$U$6:$U$205,0))) | D49: =IF(B49="","",INDEX(Positionen!$Q$6:$Q$205,MATCH(20,Positionen!$U$6:$U$205,0))) | E49: =IF(B49="","",IF(INDEX(Positionen!$F$6:$F$205,MATCH(20,Positionen!$U$6:$U$205,0))="","",INDEX(Positionen!$F$6:$F$205,MATCH(20,Positionen!$U$6:$U$205,0)))) | F49: =IF(B49="","",IF(INDEX(Positionen!$G$6:$G$205,MATCH(20,Positionen!$U$6:$U$205,0))="","",INDEX(Positionen!$G$6:$G$205,MATCH(20,Positionen!$U$6:$U$205,0)))) | G49: =IF(B49="","",IF(INDEX(Positionen!$H$6:$H$205,MATCH(20,Positionen!$U$6:$U$205,0))="","",INDEX(Positionen!$H$6:$H$205,MATCH(20,Positionen!$U$6:$U$205,0)))) | H49: =IF(B49="","",INDEX(Positionen!$L$6:$L$205,MATCH(20,Positionen!$U$6:$U$205,0))) | I49: =IF(B49="","",INDEX(Positionen!$S$6:$S$205,MATCH(20,Positionen!$U$6:$U$205,0))) | J49: =IF(B49="","",IF(INDEX(Positionen!$N$6:$N$205,MATCH(20,Positionen!$U$6:$U$205,0))="","",INDEX(Positionen!$N$6:$N$205,MATCH(20,Positionen!$U$6:$U$205,0))))
A50: =IF(B50="","",INDEX(Positionen!$A$6:$A$205,MATCH(21,Positionen!$U$6:$U$205,0))&"") | B50: =IFERROR(INDEX(Positionen!$B$6:$B$205,MATCH(21,Positionen!$U$6:$U$205,0)),"") | C50: =IF(B50="","",INDEX(Positionen!$P$6:$P$205,MATCH(21,Positionen!$U$6:$U$205,0))) | D50: =IF(B50="","",INDEX(Positionen!$Q$6:$Q$205,MATCH(21,Positionen!$U$6:$U$205,0))) | E50: =IF(B50="","",IF(INDEX(Positionen!$F$6:$F$205,MATCH(21,Positionen!$U$6:$U$205,0))="","",INDEX(Positionen!$F$6:$F$205,MATCH(21,Positionen!$U$6:$U$205,0)))) | F50: =IF(B50="","",IF(INDEX(Positionen!$G$6:$G$205,MATCH(21,Positionen!$U$6:$U$205,0))="","",INDEX(Positionen!$G$6:$G$205,MATCH(21,Positionen!$U$6:$U$205,0)))) | G50: =IF(B50="","",IF(INDEX(Positionen!$H$6:$H$205,MATCH(21,Positionen!$U$6:$U$205,0))="","",INDEX(Positionen!$H$6:$H$205,MATCH(21,Positionen!$U$6:$U$205,0)))) | H50: =IF(B50="","",INDEX(Positionen!$L$6:$L$205,MATCH(21,Positionen!$U$6:$U$205,0))) | I50: =IF(B50="","",INDEX(Positionen!$S$6:$S$205,MATCH(21,Positionen!$U$6:$U$205,0))) | J50: =IF(B50="","",IF(INDEX(Positionen!$N$6:$N$205,MATCH(21,Positionen!$U$6:$U$205,0))="","",INDEX(Positionen!$N$6:$N$205,MATCH(21,Positionen!$U$6:$U$205,0))))
A51: =IF(B51="","",INDEX(Positionen!$A$6:$A$205,MATCH(22,Positionen!$U$6:$U$205,0))&"") | B51: =IFERROR(INDEX(Positionen!$B$6:$B$205,MATCH(22,Positionen!$U$6:$U$205,0)),"") | C51: =IF(B51="","",INDEX(Positionen!$P$6:$P$205,MATCH(22,Positionen!$U$6:$U$205,0))) | D51: =IF(B51="","",INDEX(Positionen!$Q$6:$Q$205,MATCH(22,Positionen!$U$6:$U$205,0))) | E51: =IF(B51="","",IF(INDEX(Positionen!$F$6:$F$205,MATCH(22,Positionen!$U$6:$U$205,0))="","",INDEX(Positionen!$F$6:$F$205,MATCH(22,Positionen!$U$6:$U$205,0)))) | F51: =IF(B51="","",IF(INDEX(Positionen!$G$6:$G$205,MATCH(22,Positionen!$U$6:$U$205,0))="","",INDEX(Positionen!$G$6:$G$205,MATCH(22,Positionen!$U$6:$U$205,0)))) | G51: =IF(B51="","",IF(INDEX(Positionen!$H$6:$H$205,MATCH(22,Positionen!$U$6:$U$205,0))="","",INDEX(Positionen!$H$6:$H$205,MATCH(22,Positionen!$U$6:$U$205,0)))) | H51: =IF(B51="","",INDEX(Positionen!$L$6:$L$205,MATCH(22,Positionen!$U$6:$U$205,0))) | I51: =IF(B51="","",INDEX(Positionen!$S$6:$S$205,MATCH(22,Positionen!$U$6:$U$205,0))) | J51: =IF(B51="","",IF(INDEX(Positionen!$N$6:$N$205,MATCH(22,Positionen!$U$6:$U$205,0))="","",INDEX(Positionen!$N$6:$N$205,MATCH(22,Positionen!$U$6:$U$205,0))))
A52: =IF(B52="","",INDEX(Positionen!$A$6:$A$205,MATCH(23,Positionen!$U$6:$U$205,0))&"") | B52: =IFERROR(INDEX(Positionen!$B$6:$B$205,MATCH(23,Positionen!$U$6:$U$205,0)),"") | C52: =IF(B52="","",INDEX(Positionen!$P$6:$P$205,MATCH(23,Positionen!$U$6:$U$205,0))) | D52: =IF(B52="","",INDEX(Positionen!$Q$6:$Q$205,MATCH(23,Positionen!$U$6:$U$205,0))) | E52: =IF(B52="","",IF(INDEX(Positionen!$F$6:$F$205,MATCH(23,Positionen!$U$6:$U$205,0))="","",INDEX(Positionen!$F$6:$F$205,MATCH(23,Positionen!$U$6:$U$205,0)))) | F52: =IF(B52="","",IF(INDEX(Positionen!$G$6:$G$205,MATCH(23,Positionen!$U$6:$U$205,0))="","",INDEX(Positionen!$G$6:$G$205,MATCH(23,Positionen!$U$6:$U$205,0)))) | G52: =IF(B52="","",IF(INDEX(Positionen!$H$6:$H$205,MATCH(23,Positionen!$U$6:$U$205,0))="","",INDEX(Positionen!$H$6:$H$205,MATCH(23,Positionen!$U$6:$U$205,0)))) | H52: =IF(B52="","",INDEX(Positionen!$L$6:$L$205,MATCH(23,Positionen!$U$6:$U$205,0))) | I52: =IF(B52="","",INDEX(Positionen!$S$6:$S$205,MATCH(23,Positionen!$U$6:$U$205,0))) | J52: =IF(B52="","",IF(INDEX(Positionen!$N$6:$N$205,MATCH(23,Positionen!$U$6:$U$205,0))="","",INDEX(Positionen!$N$6:$N$205,MATCH(23,Positionen!$U$6:$U$205,0))))
A53: =IF(B53="","",INDEX(Positionen!$A$6:$A$205,MATCH(24,Positionen!$U$6:$U$205,0))&"") | B53: =IFERROR(INDEX(Positionen!$B$6:$B$205,MATCH(24,Positionen!$U$6:$U$205,0)),"") | C53: =IF(B53="","",INDEX(Positionen!$P$6:$P$205,MATCH(24,Positionen!$U$6:$U$205,0))) | D53: =IF(B53="","",INDEX(Positionen!$Q$6:$Q$205,MATCH(24,Positionen!$U$6:$U$205,0))) | E53: =IF(B53="","",IF(INDEX(Positionen!$F$6:$F$205,MATCH(24,Positionen!$U$6:$U$205,0))="","",INDEX(Positionen!$F$6:$F$205,MATCH(24,Positionen!$U$6:$U$205,0)))) | F53: =IF(B53="","",IF(INDEX(Positionen!$G$6:$G$205,MATCH(24,Positionen!$U$6:$U$205,0))="","",INDEX(Positionen!$G$6:$G$205,MATCH(24,Positionen!$U$6:$U$205,0)))) | G53: =IF(B53="","",IF(INDEX(Positionen!$H$6:$H$205,MATCH(24,Positionen!$U$6:$U$205,0))="","",INDEX(Positionen!$H$6:$H$205,MATCH(24,Positionen!$U$6:$U$205,0)))) | H53: =IF(B53="","",INDEX(Positionen!$L$6:$L$205,MATCH(24,Positionen!$U$6:$U$205,0))) | I53: =IF(B53="","",INDEX(Positionen!$S$6:$S$205,MATCH(24,Positionen!$U$6:$U$205,0))) | J53: =IF(B53="","",IF(INDEX(Positionen!$N$6:$N$205,MATCH(24,Positionen!$U$6:$U$205,0))="","",INDEX(Positionen!$N$6:$N$205,MATCH(24,Positionen!$U$6:$U$205,0))))
...

Sheet Materialauszug
S1: =MAX(1,COUNT(Positionen!$V$6:$V$205),COUNT(Positionen!$W$6:$W$205),COUNT(Positionen!$Y$6:$Y$205))
A4: MATERIALAUSZUG | G4: =IF(P_NR="","",P_NR&" · "&P_NAME) | Q4: =IF(P_DATUM="","","Stand "&P_DATUM)
A7: Positionen | B7: Stück | D7: Laufmeter | G7: Fläche | H7: Gewicht | J7: davon beschichten | M7: Tafeln (Empfehlung)
A8: =COUNT(Positionen!$AC$6:$AC$205) | B8: =SUM(Positionen!$H$6:$H$205) | D8: =SUM(Positionen!$K$6:$K$205) | G8: =SUM(Positionen!$L$6:$L$205) | H8: =SUM(Positionen!$M$6:$M$205) | J8: =SUMIFS(Positionen!$L$6:$L$205,Positionen!$R$6:$R$205,"Ja") | M8: =SUM(Tafelbedarf!$H$9:$H$48)
A10: NACH BAUTEIL | G10: NACH MATERIAL / DICKE | M10: NACH LAGE / FASSADE
A11: Bauteil | B11: Stk | C11: lfm | D11: m² | E11: kg | G11: Material · Dicke | H11: Stk | I11: lfm | J11: m² | K11: kg | M11: Lage | N11: Stk | O11: lfm | P11: m² | Q11: kg
A12: Total | B12: =SUM(B13:B52) | C12: =SUM(C13:C52) | D12: =SUM(D13:D52) | E12: =SUM(E13:E52) | G12: Total | H12: =SUM(H13:H52) | I12: =SUM(I13:I52) | J12: =SUM(J13:J52) | K12: =SUM(K13:K52) | M12: Total | N12: =SUM(N13:N52) | O12: =SUM(O13:O52) | P12: =SUM(P13:P52) | Q12: =SUM(Q13:Q52)
A13: =IFERROR(INDEX(Positionen!$B$6:$B$205,MATCH(1,Positionen!$V$6:$V$205,0)),"") | B13: =IF(A13="","",SUMIFS(Positionen!$H$6:$H$205,Positionen!$B$6:$B$205,A13)) | C13: =IF(A13="","",SUMIFS(Positionen!$K$6:$K$205,Positionen!$B$6:$B$205,A13)) | D13: =IF(A13="","",SUMIFS(Positionen!$L$6:$L$205,Positionen!$B$6:$B$205,A13)) | E13: =IF(A13="","",SUMIFS(Positionen!$M$6:$M$205,Positionen!$B$6:$B$205,A13)) | G13: =IFERROR(INDEX(Positionen!$T$6:$T$205,MATCH(1,Positionen!$W$6:$W$205,0)),"") | H13: =IF(G13="","",SUMIFS(Positionen!$H$6:$H$205,Positionen!$T$6:$T$205,G13)) | I13: =IF(G13="","",SUMIFS(Positionen!$K$6:$K$205,Positionen!$T$6:$T$205,G13)) | J13: =IF(G13="","",SUMIFS(Positionen!$L$6:$L$205,Positionen!$T$6:$T$205,G13)) | K13: =IF(G13="","",SUMIFS(Positionen!$M$6:$M$205,Positionen!$T$6:$T$205,G13)) | M13: =IFERROR(INDEX(Positionen!$X$6:$X$205,MATCH(1,Positionen!$Y$6:$Y$205,0)),"") | N13: =IF(M13="","",SUMIFS(Positionen!$H$6:$H$205,Positionen!$X$6:$X$205,M13)) | O13: =IF(M13="","",SUMIFS(Positionen!$K$6:$K$205,Positionen!$X$6:$X$205,M13)) | P13: =IF(M13="","",SUMIFS(Positionen!$L$6:$L$205,Positionen!$X$6:$X$205,M13)) | Q13: =IF(M13="","",SUMIFS(Positionen!$M$6:$M$205,Positionen!$X$6:$X$205,M13))
A14: =IFERROR(INDEX(Positionen!$B$6:$B$205,MATCH(2,Positionen!$V$6:$V$205,0)),"") | B14: =IF(A14="","",SUMIFS(Positionen!$H$6:$H$205,Positionen!$B$6:$B$205,A14)) | C14: =IF(A14="","",SUMIFS(Positionen!$K$6:$K$205,Positionen!$B$6:$B$205,A14)) | D14: =IF(A14="","",SUMIFS(Positionen!$L$6:$L$205,Positionen!$B$6:$B$205,A14)) | E14: =IF(A14="","",SUMIFS(Positionen!$M$6:$M$205,Positionen!$B$6:$B$205,A14)) | G14: =IFERROR(INDEX(Positionen!$T$6:$T$205,MATCH(2,Positionen!$W$6:$W$205,0)),"") | H14: =IF(G14="","",SUMIFS(Positionen!$H$6:$H$205,Positionen!$T$6:$T$205,G14)) | I14: =IF(G14="","",SUMIFS(Positionen!$K$6:$K$205,Positionen!$T$6:$T$205,G14)) | J14: =IF(G14="","",SUMIFS(Positionen!$L$6:$L$205,Positionen!$T$6:$T$205,G14)) | K14: =IF(G14="","",SUMIFS(Positionen!$M$6:$M$205,Positionen!$T$6:$T$205,G14)) | M14: =IFERROR(INDEX(Positionen!$X$6:$X$205,MATCH(2,Positionen!$Y$6:$Y$205,0)),"") | N14: =IF(M14="","",SUMIFS(Positionen!$H$6:$H$205,Positionen!$X$6:$X$205,M14)) | O14: =IF(M14="","",SUMIFS(Positionen!$K$6:$K$205,Positionen!$X$6:$X$205,M14)) | P14: =IF(M14="","",SUMIFS(Positionen!$L$6:$L$205,Positionen!$X$6:$X$205,M14)) | Q14: =IF(M14="","",SUMIFS(Positionen!$M$6:$M$205,Positionen!$X$6:$X$205,M14))
A15: =IFERROR(INDEX(Positionen!$B$6:$B$205,MATCH(3,Positionen!$V$6:$V$205,0)),"") | B15: =IF(A15="","",SUMIFS(Positionen!$H$6:$H$205,Positionen!$B$6:$B$205,A15)) | C15: =IF(A15="","",SUMIFS(Positionen!$K$6:$K$205,Positionen!$B$6:$B$205,A15)) | D15: =IF(A15="","",SUMIFS(Positionen!$L$6:$L$205,Positionen!$B$6:$B$205,A15)) | E15: =IF(A15="","",SUMIFS(Positionen!$M$6:$M$205,Positionen!$B$6:$B$205,A15)) | G15: =IFERROR(INDEX(Positionen!$T$6:$T$205,MATCH(3,Positionen!$W$6:$W$205,0)),"") | H15: =IF(G15="","",SUMIFS(Positionen!$H$6:$H$205,Positionen!$T$6:$T$205,G15)) | I15: =IF(G15="","",SUMIFS(Positionen!$K$6:$K$205,Positionen!$T$6:$T$205,G15)) | J15: =IF(G15="","",SUMIFS(Positionen!$L$6:$L$205,Positionen!$T$6:$T$205,G15)) | K15: =IF(G15="","",SUMIFS(Positionen!$M$6:$M$205,Positionen!$T$6:$T$205,G15)) | M15: =IFERROR(INDEX(Positionen!$X$6:$X$205,MATCH(3,Positionen!$Y$6:$Y$205,0)),"") | N15: =IF(M15="","",SUMIFS(Positionen!$H$6:$H$205,Positionen!$X$6:$X$205,M15)) | O15: =IF(M15="","",SUMIFS(Positionen!$K$6:$K$205,Positionen!$X$6:$X$205,M15)) | P15: =IF(M15="","",SUMIFS(Positionen!$L$6:$L$205,Positionen!$X$6:$X$205,M15)) | Q15: =IF(M15="","",SUMIFS(Positionen!$M$6:$M$205,Positionen!$X$6:$X$205,M15))
A16: =IFERROR(INDEX(Positionen!$B$6:$B$205,MATCH(4,Positionen!$V$6:$V$205,0)),"") | B16: =IF(A16="","",SUMIFS(Positionen!$H$6:$H$205,Positionen!$B$6:$B$205,A16)) | C16: =IF(A16="","",SUMIFS(Positionen!$K$6:$K$205,Positionen!$B$6:$B$205,A16)) | D16: =IF(A16="","",SUMIFS(Positionen!$L$6:$L$205,Positionen!$B$6:$B$205,A16)) | E16: =IF(A16="","",SUMIFS(Positionen!$M$6:$M$205,Positionen!$B$6:$B$205,A16)) | G16: =IFERROR(INDEX(Positionen!$T$6:$T$205,MATCH(4,Positionen!$W$6:$W$205,0)),"") | H16: =IF(G16="","",SUMIFS(Positionen!$H$6:$H$205,Positionen!$T$6:$T$205,G16)) | I16: =IF(G16="","",SUMIFS(Positionen!$K$6:$K$205,Positionen!$T$6:$T$205,G16)) | J16: =IF(G16="","",SUMIFS(Positionen!$L$6:$L$205,Positionen!$T$6:$T$205,G16)) | K16: =IF(G16="","",SUMIFS(Positionen!$M$6:$M$205,Positionen!$T$6:$T$205,G16)) | M16: =IFERROR(INDEX(Positionen!$X$6:$X$205,MATCH(4,Positionen!$Y$6:$Y$205,0)),"") | N16: =IF(M16="","",SUMIFS(Positionen!$H$6:$H$205,Positionen!$X$6:$X$205,M16)) | O16: =IF(M16="","",SUMIFS(Positionen!$K$6:$K$205,Positionen!$X$6:$X$205,M16)) | P16: =IF(M16="","",SUMIFS(Positionen!$L$6:$L$205,Positionen!$X$6:$X$205,M16)) | Q16: =IF(M16="","",SUMIFS(Positionen!$M$6:$M$205,Positionen!$X$6:$X$205,M16))
A17: =IFERROR(INDEX(Positionen!$B$6:$B$205,MATCH(5,Positionen!$V$6:$V$205,0)),"") | B17: =IF(A17="","",SUMIFS(Positionen!$H$6:$H$205,Positionen!$B$6:$B$205,A17)) | C17: =IF(A17="","",SUMIFS(Positionen!$K$6:$K$205,Positionen!$B$6:$B$205,A17)) | D17: =IF(A17="","",SUMIFS(Positionen!$L$6:$L$205,Positionen!$B$6:$B$205,A17)) | E17: =IF(A17="","",SUMIFS(Positionen!$M$6:$M$205,Positionen!$B$6:$B$205,A17)) | G17: =IFERROR(INDEX(Positionen!$T$6:$T$205,MATCH(5,Positionen!$W$6:$W$205,0)),"") | H17: =IF(G17="","",SUMIFS(Positionen!$H$6:$H$205,Positionen!$T$6:$T$205,G17)) | I17: =IF(G17="","",SUMIFS(Positionen!$K$6:$K$205,Positionen!$T$6:$T$205,G17)) | J17: =IF(G17="","",SUMIFS(Positionen!$L$6:$L$205,Positionen!$T$6:$T$205,G17)) | K17: =IF(G17="","",SUMIFS(Positionen!$M$6:$M$205,Positionen!$T$6:$T$205,G17)) | M17: =IFERROR(INDEX(Positionen!$X$6:$X$205,MATCH(5,Positionen!$Y$6:$Y$205,0)),"") | N17: =IF(M17="","",SUMIFS(Positionen!$H$6:$H$205,Positionen!$X$6:$X$205,M17)) | O17: =IF(M17="","",SUMIFS(Positionen!$K$6:$K$205,Positionen!$X$6:$X$205,M17)) | P17: =IF(M17="","",SUMIFS(Positionen!$L$6:$L$205,Positionen!$X$6:$X$205,M17)) | Q17: =IF(M17="","",SUMIFS(Positionen!$M$6:$M$205,Positionen!$X$6:$X$205,M17))
A18: =IFERROR(INDEX(Positionen!$B$6:$B$205,MATCH(6,Positionen!$V$6:$V$205,0)),"") | B18: =IF(A18="","",SUMIFS(Positionen!$H$6:$H$205,Positionen!$B$6:$B$205,A18)) | C18: =IF(A18="","",SUMIFS(Positionen!$K$6:$K$205,Positionen!$B$6:$B$205,A18)) | D18: =IF(A18="","",SUMIFS(Positionen!$L$6:$L$205,Positionen!$B$6:$B$205,A18)) | E18: =IF(A18="","",SUMIFS(Positionen!$M$6:$M$205,Positionen!$B$6:$B$205,A18)) | G18: =IFERROR(INDEX(Positionen!$T$6:$T$205,MATCH(6,Positionen!$W$6:$W$205,0)),"") | H18: =IF(G18="","",SUMIFS(Positionen!$H$6:$H$205,Positionen!$T$6:$T$205,G18)) | I18: =IF(G18="","",SUMIFS(Positionen!$K$6:$K$205,Positionen!$T$6:$T$205,G18)) | J18: =IF(G18="","",SUMIFS(Positionen!$L$6:$L$205,Positionen!$T$6:$T$205,G18)) | K18: =IF(G18="","",SUMIFS(Positionen!$M$6:$M$205,Positionen!$T$6:$T$205,G18)) | M18: =IFERROR(INDEX(Positionen!$X$6:$X$205,MATCH(6,Positionen!$Y$6:$Y$205,0)),"") | N18: =IF(M18="","",SUMIFS(Positionen!$H$6:$H$205,Positionen!$X$6:$X$205,M18)) | O18: =IF(M18="","",SUMIFS(Positionen!$K$6:$K$205,Positionen!$X$6:$X$205,M18)) | P18: =IF(M18="","",SUMIFS(Positionen!$L$6:$L$205,Positionen!$X$6:$X$205,M18)) | Q18: =IF(M18="","",SUMIFS(Positionen!$M$6:$M$205,Positionen!$X$6:$X$205,M18))
A19: =IFERROR(INDEX(Positionen!$B$6:$B$205,MATCH(7,Positionen!$V$6:$V$205,0)),"") | B19: =IF(A19="","",SUMIFS(Positionen!$H$6:$H$205,Positionen!$B$6:$B$205,A19)) | C19: =IF(A19="","",SUMIFS(Positionen!$K$6:$K$205,Positionen!$B$6:$B$205,A19)) | D19: =IF(A19="","",SUMIFS(Positionen!$L$6:$L$205,Positionen!$B$6:$B$205,A19)) | E19: =IF(A19="","",SUMIFS(Positionen!$M$6:$M$205,Positionen!$B$6:$B$205,A19)) | G19: =IFERROR(INDEX(Positionen!$T$6:$T$205,MATCH(7,Positionen!$W$6:$W$205,0)),"") | H19: =IF(G19="","",SUMIFS(Positionen!$H$6:$H$205,Positionen!$T$6:$T$205,G19)) | I19: =IF(G19="","",SUMIFS(Positionen!$K$6:$K$205,Positionen!$T$6:$T$205,G19)) | J19: =IF(G19="","",SUMIFS(Positionen!$L$6:$L$205,Positionen!$T$6:$T$205,G19)) | K19: =IF(G19="","",SUMIFS(Positionen!$M$6:$M$205,Positionen!$T$6:$T$205,G19)) | M19: =IFERROR(INDEX(Positionen!$X$6:$X$205,MATCH(7,Positionen!$Y$6:$Y$205,0)),"") | N19: =IF(M19="","",SUMIFS(Positionen!$H$6:$H$205,Positionen!$X$6:$X$205,M19)) | O19: =IF(M19="","",SUMIFS(Positionen!$K$6:$K$205,Positionen!$X$6:$X$205,M19)) | P19: =IF(M19="","",SUMIFS(Positionen!$L$6:$L$205,Positionen!$X$6:$X$205,M19)) | Q19: =IF(M19="","",SUMIFS(Positionen!$M$6:$M$205,Positionen!$X$6:$X$205,M19))
